Workbook

Sheet Consultas
A1: Tipo | B1: PED | C1: COD WEB | D1: 2-Empresa | E1: 3-Cliente | F1: 4-Total Ped. R$ | G1: Desconto Ped | H1: 5-Faturado | I1: 6-Entrada | J1: 7-Quant. Grande? | K1: 8-Prod. Q Ñ Combinam? | L1: Armário ou Cofre > 2.000 | M1: Entrega=Cadastro | N1: UF do Cliente | O1: Google Maps 0|5|10 | P1: Registro.Br | Q1: ScamAdvizer | R1: 9-Pgtos Abertos | S1: 10-Comprou e pagou? | T1: 10-Comprou e pagou +5X? | U1: 11-Cadastro=Receita | V1: 12-CNPJ Ativo | W1: 14-Casa/Sala/Conj/Apart no end. | X1: EmailSiteReceita=@corporativo? | Y1: Existe Mail Financeiro Diferente? | Z1: 15-Mail gratuito | AA1: 16-Possui Site | AB1: 18-Fundação Matriz | AC1: 20-Grande /Conhecida/Filiais | AD1: 29-Capital Soc. (Matriz) | AE1: 25-SalvarPDFConsltRede | AF1: 24-PFIN S ou N | AG1: 23-Ch s/ Fundo | AH1: 21-Protestos S ou N | AI1: 22-Vlr Prot. (número) | AJ1: 28 - SCORE Serasa | AK1: Nome que consta na consulta REGULARIDADE DO FGTS | AL1: Situação Regular? | AM1: 33-RAZÃO E FGTS IGUAL?S/N | AN1: 34-Tem Certid Trib Mobiliar.? | AO1: 30-3 NF Conf. | AP1: 31 - Conta de Luz | AQ1: OBS | AR1: Final: Lib/Entrada/Bloqu. só AV | AS1: Data | AT1: Total Score | AU1: Risco | AV1: Sugestão | AW1: Obs: | AX1: Contratato Entrega | AY1: Perigo de Golpe | AZ1: Cadastro = Receita
A2: ='Parâmetros'!$A$19 -> Rel. Básico PJ | B2: 162 | C2: 24896 | D2: Metalpleno | E2: 034331 | F2: 11700 | G2: OK | H2: S | I2: N | J2: N | K2: N | L2: S | M2: N | N2: SC | O2: 0 | P2: N | Q2: 100 | R2: N | S2: S | T2: N | U2: S | V2: S | W2: N | X2: S | Y2: S | Z2: N | AA2: S | AB2: 34935 | AC2: N | AD2: R$ 40.740.000,00 | AE2: S | AF2: N | AG2: N | AH2: N | AI2: 0 | AJ2: 982 | AK2: FAST INDUSTRIA E COMERCIO LTDA | AL2: S | AM2: S | AN2: D | AO2: N/D | AP2: N/D | AQ2: Transportadora Faoli transportes ok | AR2: Liberado | AS2: 46127 | AT2: =Calculo!AQ2 -> 45 | AU2: =Calculo!AV2 -> SEM-RISCO | AV2: =Calculo!AW2 -> LIBERADO | AW2: =Calculo!AX2 -> SOLICITAR PED COMPRA | AX2: =Calculo!K2 -> SOLIC CONTRATO DE ENTREGA | AY2: =Calculo!AY2 -> CHECAGEM REVERSA | AZ2: =Calculo!AZ2 -> N/A
A3: ='Parâmetros'!$A$19 -> Rel. Básico PJ | B3: 166 | C3: 24879 | D3: Metalpleno | E3: 141660 | F3: 12931 | G3: OK | H3: S | I3: S | J3: N | K3: N | L3: S | M3: S | N3: RS | O3: 5 | P3: N | Q3: 100 | R3: N | S3: N | T3: N | U3: S | V3: S | W3: N | X3: S | Y3: S | Z3: N | AA3: S | AB3: 24323 | AC3: N | AD3: R$ 29.200.000,00 | AE3: S | AF3: S | AG3: N | AH3: N | AI3: 20724.06 | AJ3: 699 | AK3: FARINA SA COMPONENTES AUTOMOTIVOS | AL3: S | AM3: S | AN3: D | AO3: N/D | AP3: N/D | AR3: Liberado | AS3: 46129 | AT3: =Calculo!AQ3 -> 56 | AU3: =Calculo!AV3 -> SEM-RISCO | AV3: =Calculo!AW3 -> LIBERADO | AW3: =Calculo!AX3 -> SOLICITAR PED COMPRA | AX3: =Calculo!K3 -> SOLIC CONTRATO DE ENTREGA | AY3: =Calculo!AY3 -> N/A | AZ3: =Calculo!AZ3 -> N/A
A4: ='Parâmetros'!$A$19 -> Rel. Básico PJ | B4: 167 | C4: 25087 | D4: Metalpleno | E4: 144468 | F4: 4100 | G4: OK | H4: S | I4: S | J4: N | K4: N | L4: S | M4: S | N4: RS | O4: 5 | P4: S | Q4: 100 | R4: N | S4: N | T4: N | U4: S | V4: S | W4: S | X4: S | Y4: N | Z4: N | AA4: S | AB4: 38422 | AC4: N | AD4: R$ 50.000,00 | AE4: S | AF4: N | AG4: N | AH4: N | AI4: 0 | AJ4: 651 | AK4: NEW TECH INFORMATICA LTDA | AL4: S | AM4: S | AN4: D | AO4: N/D | AP4: N/D | AR4: Liberado | AS4: 46129 | AT4: =Calculo!AQ4 -> 45 | AU4: =Calculo!AV4 -> SEM-RISCO | AV4: =Calculo!AW4 -> LIBERADO | AW4: =Calculo!AX4 -> N/A | AX4: =Calculo!K4 -> SOLIC CONTRATO DE ENTREGA | AY4: =Calculo!AY4 -> N/A | AZ4: =Calculo!AZ4 -> N/A
A5: ='Parâmetros'!$A$19 -> Rel. Básico PJ | B5: 1864 | C5: 25085 | D5: GsiBW | E5: 021332 | F5: 1180 | G5: OK | H5: S | I5: N | J5: N | K5: N | L5: N | M5: S | N5: SP | O5: - | P5: N | Q5: 100 | R5: N | S5: S | T5: N | U5: S | V5: S | W5: N | X5: S | Y5: S | Z5: N | AA5: S | AB5: 30467 | AC5: N | AD5: R$ 42.171.656,00 | AE5: S | AF5: N | AG5: N | AH5: N | AI5: 0 | AJ5: 1000 | AK5: LEVITARE-INDUSTRIA E COMERCIO DE LATICINIOS LTDA | AL5: S | AM5: S | AN5: D | AO5: N/D | AP5: N/D | AR5: Liberado | AS5: 46134 | AT5: =Calculo!AQ5 -> 59 | AU5: =Calculo!AV5 -> SEM-RISCO | AV5: =Calculo!AW5 -> LIBERADO | AW5: =Calculo!AX5 -> N/A | AX5: =Calculo!K5 -> N/A | AY5: =Calculo!AY5 -> N/A | AZ5: =Calculo!AZ5 -> N/A
A6: ='Parâmetros'!$A$19 -> Rel. Básico PJ | B6: 442 | C6: 25081 | D6: Oaco | E6: 144469 | F6: 679 | G6: OK | H6: S | I6: N | J6: N | K6: N | L6: N | M6: S | N6: PR | O6: - | P6: N | Q6: 100 | R6: N | S6: N | T6: N | U6: S | V6: S | W6: N | X6: S | Y6: S | Z6: N | AA6: S | AB6: 42863 | AC6: S | AD6: R$ 5.000.000,00 | AE6: S | AF6: S | AG6: N | AH6: S | AI6: 520974.26 | AJ6: 826 | AK6: GF4 PARTICIPACOES LTDA | AL6: S | AM6: S | AN6: D | AO6: N/D | AP6: N/D | AQ6: Pedido cancelado | AR6: Liberado | AS6: 46134 | AT6: =Calculo!AQ6 -> 13 | AU6: =Calculo!AV6 -> SEM-RISCO | AV6: =Calculo!AW6 -> LIBERADO | AW6: =Calculo!AX6 -> N/A | AX6: =Calculo!K6 -> N/A | AY6: =Calculo!AY6 -> N/A | AZ6: =Calculo!AZ6 -> N/A
A7: ='Parâmetros'!$A$19 -> Rel. Básico PJ | B7: 444 | C7: 25091 | D7: Oaco | E7: 144471 | F7: 679 | G7: OK | H7: S | I7: N | J7: N | K7: N | L7: N | M7: S | N7: PR | O7: - | P7: N | Q7: 100 | R7: N | S7: N | T7: N | U7: S | V7: S | W7: N | X7: S | Y7: S | Z7: N | AA7: S | AB7: 42863 | AC7: S | AD7: R$ 5.000.000,00 | AE7: S | AF7: S | AG7: N | AH7: S | AI7: 520974.26 | AJ7: 826 | AK7: GF4 PARTICIPACOES LTDA | AL7: S | AM7: S | AN7: D | AO7: N/D | AP7: N/D | AQ7: Pedido cancelado | AR7: Liberado | AS7: 46134 | AT7: =Calculo!AQ7 -> 13 | AU7: =Calculo!AV7 -> SEM-RISCO | AV7: =Calculo!AW7 -> LIBERADO | AW7: =Calculo!AX7 -> N/A | AX7: =Calculo!K7 -> N/A | AY7: =Calculo!AY7 -> N/A | AZ7: =Calculo!AZ7 -> N/A
A8: ='Parâmetros'!$A$19 -> Rel. Básico PJ | D8: Metalpleno | F8: 12804 | G8: OK | H8: S | I8: N | J8: N | K8: N | L8: S | M8: N | N8: SP | O8: 0 | P8: S | Q8: 100 | R8: N | S8: N | T8: N | U8: S | V8: S | W8: S | X8: S | Y8: N | Z8: N | AA8: S | AB8: 39654 | AC8: S | AD8: R$ 184.120.000,00 | AE8: S | AF8: S | AG8: N | AH8: N | AI8: 1413.88 | AJ8: 797 | AK8: RG LOG LOGISTICA E TRANSPORTE LTDA | AL8: S | AM8: S | AN8: D | AO8: N/D | AP8: N/D | AQ8: Pré análise-Andrea | AR8: Liberado | AS8: 46134 | AT8: =Calculo!AQ8 -> 21 | AU8: =Calculo!AV8 -> SEM-RISCO | AV8: =Calculo!AW8 -> LIBERADO | AW8: =Calculo!AX8 -> SOLICITAR PED COMPRA | AX8: =Calculo!K8 -> SOLIC CONTRATO DE ENTREGA | AY8: =Calculo!AY8 -> CHECAGEM REVERSA | AZ8: =Calculo!AZ8 -> N/A
A9: ='Parâmetros'!$A$19 -> Rel. Básico PJ | B9: 446 | C9: 25094 | D9: Oaco | E9: 144472 | F9: 2370.14 | G9: OK | H9: S | I9: N | J9: N | K9: N | L9: S | M9: S | N9: RJ | O9: 5 | Q9: 100 | R9: N | S9: N | T9: N | U9: S | V9: S | W9: N | X9: S | Y9: S | Z9: N | AA9: S | AB9: 45366 | AC9: N | AD9: R$ 100.000,00 | AE9: S | AF9: N | AG9: N | AH9: S | AI9: 68159.59 | AK9: ECOSI METAIS E ACESSORIOS LTDA | AL9: S | AM9: S | AN9: D | AO9: N/D | AP9: N/D | AR9: Bloqueado | AS9: 46134 | AT9: =Calculo!AQ9 -> -29 | AU9: =Calculo!AV9 -> GRANDE-OU-FALINDO: | AV9: =Calculo!AW9 -> SE FALINDO SÓ ANTECIPADO | SE GRANDE BUROCR PEGAR CONTATOS FINANCEIRO | AW9: =Calculo!AX9 -> N/A | AX9: =Calculo!K9 -> SOLIC CONTRATO DE ENTREGA | AY9: =Calculo!AY9 -> N/A | AZ9: =Calculo!AZ9 -> N/A
A10: ='Parâmetros'!$A$19 -> Rel. Básico PJ | B10: 170 | C10: 25110 | D10: Metalpleno | E10: 144477 | F10: 8081 | G10: OK | H10: S | I10: S | J10: N | K10: N | L10: S | M10: S | N10: SP | O10: 5 | P10: S | Q10: 100 | R10: N | S10: N | T10: N | U10: S | V10: S | W10: N | X10: S | Y10: S | Z10: N | AA10: S | AB10: 30124 | AC10: S | AD10: R$ 879.784.955,67 | AE10: S | AF10: S | AG10: N | AH10: S | AI10: 2607178 | AK10: BOMBRIL S/A-EM RECUPERACAO JUDICIAL | AL10: S | AM10: S | AN10: D | AO10: N/D | AP10: N/D | AR10: Liberado | AS10: 46142 | AT10: =Calculo!AQ10 -> 12 | AU10: =Calculo!AV10 -> SEM-RISCO | AV10: =Calculo!AW10 -> LIBERADO | AW10: =Calculo!AX10 -> SOLICITAR PED COMPRA | AX10: =Calculo!K10 -> SOLIC CONTRATO DE ENTREGA | AY10: =Calculo!AY10 -> N/A | AZ10: =Calculo!AZ10 -> N/A
A11: ='Parâmetros'!$A$19 -> Rel. Básico PJ | B11: 172 | C11: 25148 | D11: Metalpleno | E11: 144481 | F11: 4567 | G11: OK | H11: S | I11: N | J11: N | K11: N | L11: S | M11: N | N11: SP | O11: 0 | P11: S | Q11: 100 | R11: N | S11: N | T11: N | U11: S | V11: S | W11: N | X11: S | Y11: N | Z11: N | AA11: S | AB11: 39423 | AC11: N | AD11: R$ 1.490.000,00 | AE11: S | AF11: S | AG11: N | AH11: N | AI11: 424.52 | AJ11: 745 | AK11: TECNOR INDUSTRIA E COMERCIO DE MAQUINAS E EQUIPAMENTOS | AL11: S | AM11: S | AN11: D | AO11: N/D | AP11: N/D | AR11: Liberado | AS11: 46139 | AT11: =Calculo!AQ11 -> 22 | AU11: =Calculo!AV11 -> SEM-RISCO | AV11: =Calculo!AW11 -> LIBERADO | AW11: =Calculo!AX11 -> N/A | AX11: =Calculo!K11 -> SOLIC CONTRATO DE ENTREGA | AY11: =Calculo!AY11 -> CHECAGEM REVERSA | AZ11: =Calculo!AZ11 -> N/A
A12: ='Parâmetros'!$A$19 -> Rel. Básico PJ | B12: 171 | C12: 24933 | D12: Metalpleno | E12: 144480 | F12: 4103 | G12: OK | H12: S | I12: N | J12: N | K12: N | L12: S | M12: N | N12: SC | O12: 0 | P12: - | Q12: 100 | R12: N | S12: N | T12: N | U12: S | V12: S | W12: N | X12: S | Y12: S | Z12: N | AA12: S | AB12: 39772 | AC12: N | AD12: R$ 21.300,000,00 | AE12: S | AF12: N | AG12: N | AH12: N | AI12: 0 | AJ12: 1000 | AK12: ADF EMPRESAS REUNIDAS LTDA | AL12: S | AM12: S | AN12: D | AO12: N/D | AP12: N/D | AR12: Liberado | AS12: 46139 | AT12: =Calculo!AQ12 -> 29 | AU12: =Calculo!AV12 -> SEM-RISCO | AV12: =Calculo!AW12 -> LIBERADO | AW12: =Calculo!AX12 -> N/A | AX12: =Calculo!K12 -> SOLIC CONTRATO DE ENTREGA | AY12: =Calculo!AY12 -> CHECAGEM REVERSA | AZ12: =Calculo!AZ12 -> N/A
A13: ='Parâmetros'!$A$19 -> Rel. Básico PJ | B13: 460 | C13: 25168 | D13: Oaco | E13: 144485 | F13: 2199 | G13: OK | H13: S | I13: N | J13: N | K13: N | L13: S | M13: N | N13: RS | O13: 0 | P13: S | Q13: 100 | R13: N | S13: N | T13: N | U13: S | V13: S | W13: N | X13: S | Y13: S | Z13: N | AA13: S | AB13: 38408 | AC13: N | AD13: R$ 6.041.064,00 | AE13: S | AF13: N | AG13: N | AH13: N | AI13: 0 | AJ13: 832 | AK13: MARQUESPAN ALIMENTOS LTDA | AL13: S | AM13: S | AN13: D | AO13: N/D | AP13: N/D | AQ13: MODULAR TRANSPORTES LTDA (SP) | AR13: Liberado | AS13: 46140 | AT13: =Calculo!AQ13 -> 35 | AU13: =Calculo!AV13 -> SEM-RISCO | AV13: =Calculo!AW13 -> LIBERADO | AW13: =Calculo!AX13 -> N/A | AX13: =Calculo!K13 -> SOLIC CONTRATO DE ENTREGA | AY13: =Calculo!AY13 -> CHECAGEM REVERSA | AZ13: =Calculo!AZ13 -> N/A
A14: ='Parâmetros'!$A$19 -> Rel. Básico PJ | B14: 176 | C14: 25175 | D14: Metalpleno | E14: 033086 | F14: 6402 | G14: OK | H14: S | I14: N | J14: N | K14: N | L14: S | M14: 0 | N14: SP | O14: 0 | P14: S | Q14: 100 | R14: N | S14: N | T14: N | U14: S | V14: S | W14: N | X14: S | Y14: N | Z14: N | AA14: S | AB14: 43642 | AC14: N | AD14: R$ 437.323,00 | AE14: S | AF14: N | AG14: N | AH14: N | AI14: 0 | AJ14: 902 | AK14: CYMZ CONSTRUCOES LTDA | AL14: S | AM14: S | AN14: D | AO14: N/D | AP14: N/D | AR14: Liberado | AS14: 46140 | AT14: =Calculo!AQ14 -> 24 | AU14: =Calculo!AV14 -> SEM-RISCO | AV14: =Calculo!AW14 -> LIBERADO | AW14: =Calculo!AX14 -> SOLICITAR PED COMPRA | AX14: =Calculo!K14 -> SOLIC CONTRATO DE ENTREGA | AY14: =Calculo!AY14 -> CHECAGEM REVERSA | AZ14: =Calculo!AZ14 -> N/A
A15: ='Parâmetros'!$A$19 -> Rel. Básico PJ | B15: 175 | C15: 25079 | D15: Metalpleno | E15: 005031 | F15: 6402 | G15: OK | H15: S | I15: N | J15: N | K15: N | L15: S | M15: N | N15: PA | O15: 0 | P15: N | Q15: 100 | R15: N | S15: N | T15: N | U15: S | V15: S | W15: N | X15: S | Y15: S | Z15: N | AA15: S | AB15: 31400 | AC15: N | AD15: R$ 2.548.010.108,99 | AE15: S | AF15: S | AG15: N | AH15: N | AI15: 8068.54 | AJ15: 850 | AK15: SIDERURGICA NORTE BRASIL SA | AL15: S | AM15: S | AN15: D | AO15: N/D | AP15: N/D | AR15: Liberado | AS15: 46141 | AT15: =Calculo!AQ15 -> 27 | AU15: =Calculo!AV15 -> SEM-RISCO | AV15: =Calculo!AW15 -> LIBERADO | AW15: =Calculo!AX15 -> SOLICITAR PED COMPRA | AX15: =Calculo!K15 -> SOLIC CONTRATO DE ENTREGA | AY15: =Calculo!AY15 -> CHECAGEM REVERSA | AZ15: =Calculo!AZ15 -> N/A
A16: ='Parâmetros'!$A$19 -> Rel. Básico PJ | B16: 177 | C16: 25159 | D16: Metalpleno | E16: 144489 | F16: 4103.1 | G16: OK | H16: S | I16: N | J16: N | K16: N | L16: S | M16: S | N16: SP | O16: 5 | P16: N | Q16: 100 | R16: N | S16: N | T16: N | U16: S | V16: S | W16: N | X16: S | Y16: S | Z16: N | AA16: S | AB16: 35607 | AC16: N | AD16: R$ 32.224.443,00 | AE16: S | AF16: N | AG16: N | AH16: N | AI16: 0 | AJ16: 639 | AK16: SLEEVER INTERNATIONAL LTDA | AL16: S | AM16: S | AN16: D | AO16: N/D | AP16: N/D | AR16: Liberado | AS16: 46141 | AT16: =Calculo!AQ16 -> 42 | AU16: =Calculo!AV16 -> SEM-RISCO | AV16: =Calculo!AW16 -> LIBERADO | AW16: =Calculo!AX16 -> N/A | AX16: =Calculo!K16 -> SOLIC CONTRATO DE ENTREGA | AY16: =Calculo!AY16 -> N/A | AZ16: =Calculo!AZ16 -> N/A
A17: ='Parâmetros'!$A$19 -> Rel. Básico PJ | B17: 178 | C17: 24981 | D17: Metalpleno | E17: 144490 | F17: 23405 | G17: OK | H17: S | I17: S | J17: N | K17: N | L17: S | M17: S | N17: SP | O17: 5 | P17: S | Q17: 100 | R17: N | S17: N | T17: N | U17: S | V17: S | W17: N | X17: S | Y17: S | Z17: N | AA17: S | AB17: 30124 | AC17: S | AD17: R$ 879.784.955,67 | AE17: S | AF17: S | AG17: N | AH17: N | AI17: 2607178 | AK17: BOMBRIL S/A-EM RECUPERACAO JUDICIAL | AL17: S | AM17: S | AN17: D | AO17: N/D | AP17: N/D | AR17: Liberado | AS17: 46142 | AT17: =Calculo!AQ17 -> 19 | AU17: =Calculo!AV17 -> SEM-RISCO | AV17: =Calculo!AW17 -> LIBERADO | AW17: =Calculo!AX17 -> SOLICITAR PED COMPRA | AX17: =Calculo!K17 -> SOLIC CONTRATO DE ENTREGA | AY17: =Calculo!AY17 -> N/A | AZ17: =Calculo!AZ17 -> N/A
A18: ='Parâmetros'!$A$19 -> Rel. Básico PJ | B18: 466 | C18: 25024 | D18: Oaco | E18: 028293 | F18: 4990 | G18: OK | H18: S | I18: N | J18: N | K18: N | L18: N | M18: S | N18: SP | O18: - | P18: N | Q18: 100 | R18: N | S18: S | T18: S | U18: S | V18: S | W18: N | X18: S | Y18: S | Z18: N | AA18: S | AB18: 37971 | AC18: S | AD18: R$ 15.711.359.775,89 | AE18: S | AF18: S | AG18: N | AH18: S | AI18: 42379256 | AJ18: 791 | AK18: REDE D'OR SAO LUIZ SA | AL18: S | AM18: S | AN18: D | AO18: N/D | AP18: N/D | AR18: Liberado | AS18: 46142 | AT18: =Calculo!AQ18 -> 52 | AU18: =Calculo!AV18 -> SEM-RISCO | AV18: =Calculo!AW18 -> LIBERADO | AW18: =Calculo!AX18 -> N/A | AX18: =Calculo!K18 -> N/A | AY18: =Calculo!AY18 -> N/A | AZ18: =Calculo!AZ18 -> N/A
A19: ='Parâmetros'!$A$19 -> Rel. Básico PJ | B19: 182 | C19: 24852 | D19: Metalpleno | E19: 143634 | F19: 6753.14 | G19: OK | H19: S | I19: N | J19: N | K19: N | L19: S | M19: S | N19: SP | O19: 5 | P19: N | Q19: 100 | R19: N | S19: S | T19: N | U19: S | V19: S | W19: N | X19: S | Y19: N | Z19: N | AA19: S | AB19: 31315 | AC19: S | AD19: R$ 247.060.169,00 | AE19: S | AF19: S | AG19: N | AH19: S | AI19: 1821.14 | AJ19: 868 | AK19: JM LUBRIFICANTES E PECAS P VEICULOS LTDA | AL19: S | AM19: S | AN19: D | AO19: N/D | AP19: N/D | AR19: Liberado | AS19: 46146 | AT19: =Calculo!AQ19 -> 39 | AU19: =Calculo!AV19 -> SEM-RISCO | AV19: =Calculo!AW19 -> LIBERADO | AW19: =Calculo!AX19 -> SOLICITAR PED COMPRA | AX19: =Calculo!K19 -> SOLIC CONTRATO DE ENTREGA | AY19: =Calculo!AY19 -> N/A | AZ19: =Calculo!AZ19 -> N/A
A20: ='Parâmetros'!$A$19 -> Rel. Básico PJ | B20: 185 | C20: 23478 | D20: Metalpleno | E20: 144500 | F20: 7870 | G20: OK | H20: S | I20: N | J20: N | K20: N | L20: S | M20: S | N20: GO | O20: - | P20: S | Q20: 100 | R20: N | S20: S | T20: N | U20: S | V20: S | W20: S | X20: S | Y20: N | Z20: N | AA20: S | AB20: 41884 | AC20: S | AD20: R$ 5.000,00 | AE20: S | AF20: S | AG20: N | AH20: N | AI20: 9799.56 | AK20: PREVINA CURSOS E EQUIPAMENTOS LTDA | AL20: S | AM20: S | AN20: D | AO20: N/D | AP20: N/D | AR20: Liberado | AS20: 46147 | AT20: =Calculo!AQ20 -> 9 | AU20: =Calculo!AV20 -> SEM-RISCO | AV20: =Calculo!AW20 -> LIBERADO | AW20: =Calculo!AX20 -> SOLICITAR PED COMPRA | AX20: =Calculo!K20 -> SOLIC CONTRATO DE ENTREGA | AY20: =Calculo!AY20 -> N/A | AZ20: =Calculo!AZ20 -> N/A
A21: ='Parâmetros'!$A$19 -> Rel. Básico PJ | B21: 186 | C21: 25163 | D21: Metalpleno | E21: 144343 | F21: 1794 | G21: OK | H21: S | I21: N | J21: N | K21: N | L21: N | M21: S | N21: SP | O21: 5 | P21: N | Q21: 100 | R21: N | S21: S | T21: N | U21: S | V21: S | W21: S | X21: S | Y21: N | Z21: N | AA21: S | AB21: 42496 | AC21: N | AD21: R$1.000.000,00 | AE21: S | AF21: N | AG21: N | AH21: S | AI21: 11488.72 | AJ21: 623 | AK21: CLINICA MEDICA DE NEFROLOGIA DE JUNDIAI LTDA | AL21: S | AM21: S | AN21: D | AO21: N/D | AP21: N/D | AR21: Liberado | AS21: 46147 | AT21: =Calculo!AQ21 -> 12 | AU21: =Calculo!AV21 -> SEM-RISCO | AV21: =Calculo!AW21 -> LIBERADO | AW21: =Calculo!AX21 -> N/A | AX21: =Calculo!K21 -> N/A | AY21: =Calculo!AY21 -> N/A | AZ21: =Calculo!AZ21 -> N/A
A22: ='Parâmetros'!$A$19 -> Rel. Básico PJ | B22: 187 | C22: 25247 | D22: Metalpleno | E22: 144160 | F22: 6402 | G22: OK | H22: S | I22: N | J22: N | K22: N | L22: S | M22: 0 | N22: MG | O22: - | P22: N | Q22: 100 | R22: N | S22: S | T22: N | U22: S | V22: S | W22: N | X22: S | Y22: S | Z22: N | AA22: S | AB22: 45125 | AC22: N | AD22: R$ 150.000,00 | AE22: S | AF22: N | AG22: N | AH22: N | AI22: 0 | AJ22: 699 | AK22: MD'ORE FERRAMENTAS E FIXACAO LTDA | AL22: S | AM22: S | AN22: D | AO22: N/D | AP22: N/D | AR22: Liberado | AS22: 46148 | AT22: =Calculo!AQ22 -> 30 | AU22: =Calculo!AV22 -> SEM-RISCO | AV22: =Calculo!AW22 -> LIBERADO | AW22: =Calculo!AX22 -> SOLICITAR PED COMPRA | AX22: =Calculo!K22 -> SOLIC CONTRATO DE ENTREGA | AY22: =Calculo!AY22 -> CHECAGEM REVERSA | AZ22: =Calculo!AZ22 -> N/A
A23: ='Parâmetros'!$A$19 -> Rel. Básico PJ | B23: 188 | C23: 25125 | D23: Metalpleno | E23: 144504 | F23: 4175.93 | G23: OK | H23: S | I23: N | J23: N | K23: N | L23: S | M23: S | N23: DF | O23: - | P23: N | Q23: 100 | R23: N | S23: N | T23: N | U23: S | V23: S | W23: S | X23: N | Y23: N | Z23: S | AA23: S | AB23: 42835 | AC23: N | AD23: R$ 20.000,00 | AE23: S | AF23: N | AG23: N | AH23: N | AI23: 0 | AJ23: 598 | AK23: INEB CLINICA MEDICA DE NEFROLOGIA LTDA | AL23: S | AM23: S | AN23: D | AO23: N/D | AP23: N/D | AR23: Liberado | AS23: 46149 | AT23: =Calculo!AQ23 -> 6 | AU23: =Calculo!AV23 -> SEM-RISCO | AV23: =Calculo!AW23 -> LIBERADO | AW23: =Calculo!AX23 -> N/A | AX23: =Calculo!K23 -> SOLIC CONTRATO DE ENTREGA | AY23: =Calculo!AY23 -> N/A | AZ23: =Calculo!AZ23 -> N/A
A24: ='Parâmetros'!$A$19 -> Rel. Básico PJ | B24: - | C24: - | D24: Metalpleno | E24: - | F24: 6402 | G24: OK | H24: S | I24: N | J24: N | K24: N | L24: S | M24: 0 | N24: SP | O24: - | P24: N | Q24: 100 | R24: N | S24: N | T24: N | U24: S | V24: S | W24: N | X24: S | Y24: N | Z24: N | AA24: S | AB24: 33695 | AC24: N | AD24: R$ 8.000.000,00 | AE24: S | AF24: N | AG24: N | AH24: N | AI24: 0 | AJ24: 868 | AK24: INFORMOV LTDA | AL24: S | AM24: S | AN24: D | AO24: N/D | AP24: N/D | AQ24: Pré análise Andrea | AR24: Liberado | AS24: 46150 | AT24: =Calculo!AQ24 -> 29 | AU24: =Calculo!AV24 -> SEM-RISCO | AV24: =Calculo!AW24 -> LIBERADO | AW24: =Calculo!AX24 -> SOLICITAR PED COMPRA | AX24: =Calculo!K24 -> SOLIC CONTRATO DE ENTREGA | AY24: =Calculo!AY24 -> CHECAGEM REVERSA | AZ24: =Calculo!AZ24 -> N/A
A25: ='Parâmetros'!$A$19 -> Rel. Básico PJ | B25: 1866 | C25: 25227 | D25: GsiBW | E25: 016801 | F25: 965 | G25: OK | H25: S | I25: N | J25: N | K25: N | L25: N | M25: S | N25: RS | O25: - | P25: S | Q25: 100 | R25: N | S25: S | T25: S | U25: S | V25: S | W25: N | X25: S | Y25: S | Z25: N | AA25: S | AB25: 24343 | AC25: S | AD25: R$ 39.249.899,97 | AE25: S | AF25: S | AG25: N | AH25: S | AI25: 30122330 | AK25: COMPANHIA MINUANO DE ALIMENTOS | AL25: S | AM25: S | AN25: N | AO25: N/D | AP25: N/D | AR25: Liberado | AS25: 46150 | AT25: =Calculo!AQ25 -> 28 | AU25: =Calculo!AV25 -> SEM-RISCO | AV25: =Calculo!AW25 -> LIBERADO | AW25: =Calculo!AX25 -> N/A | AX25: =Calculo!K25 -> N/A | AY25: =Calculo!AY25 -> N/A | AZ25: =Calculo!AZ25 -> N/A
A26: ='Parâmetros'!$A$19 -> Rel. Básico PJ | B26: 191 | C26: 25203 | D26: Metalpleno | E26: 143436 | F26: 7003 | G26: OK | H26: S | I26: N | J26: N | K26: N | L26: S | M26: S | N26: PR | O26: 5 | P26: N | Q26: 100 | R26: N | S26: S | T26: N | U26: S | V26: S | W26: N | X26: S | Y26: S | Z26: N | AA26: S | AB26: 42964 | AC26: N | AD26: R$ 99.800,00 | AE26: S | AF26: N | AG26: N | AH26: N | AI26: 0 | AJ26: 791 | AK26: NUTRIGENES INDUSTRIA DE PRODS NATURAIS E NUTRACEUTIC | AL26: S | AM26: S | AN26: D | AO26: N/D | AP26: N/D | AR26: Liberado | AS26: 46150 | AT26: =Calculo!AQ26 -> 54 | AU26: =Calculo!AV26 -> SEM-RISCO | AV26: =Calculo!AW26 -> LIBERADO | AW26: =Calculo!AX26 -> SOLICITAR PED COMPRA | AX26: =Calculo!K26 -> SOLIC CONTRATO DE ENTREGA | AY26: =Calculo!AY26 -> N/A | AZ26: =Calculo!AZ26 -> N/A
A27: ='Parâmetros'!$A$19 -> Rel. Básico PJ | B27: 193 | C27: 25285 | D27: Metalpleno | E27: 144160 | F27: 6402 | G27: OK | H27: S | I27: N | J27: N | K27: N | L27: S | M27: 0 | N27: MG | O27: - | P27: N | Q27: 100 | R27: N | S27: S | T27: N | U27: S | V27: S | W27: N | X27: S | Y27: S | Z27: N | AA27: S | AB27: 45125 | AC27: N | AD27: R$ 150.000,00 | AE27: S | AF27: N | AG27: N | AH27: N | AI27: 0 | AJ27: 699 | AK27: MD'ORE FERRAMENTAS E FIXACAO LTDA | AL27: S | AM27: S | AN27: D | AO27: N/D | AP27: N/D | AR27: Liberado | AS27: 46150 | AT27: =Calculo!AQ27 -> 30 | AU27: =Calculo!AV27 -> SEM-RISCO | AV27: =Calculo!AW27 -> LIBERADO | AW27: =Calculo!AX27 -> SOLICITAR PED COMPRA | AX27: =Calculo!K27 -> SOLIC CONTRATO DE ENTREGA | AY27: =Calculo!AY27 -> CHECAGEM REVERSA | AZ27: =Calculo!AZ27 -> N/A
A28: ='Parâmetros'!$A$19 -> Rel. Básico PJ | B28: 487 | C28: 25181 | D28: Oaco | E28: 144512 | F28: 614 | G28: OK | H28: S | I28: N | J28: N | K28: N | L28: N | M28: S | N28: RS | O28: - | P28: S | Q28: 100 | R28: N | S28: S | T28: S | U28: S | V28: S | W28: N | X28: S | Y28: N | Z28: N | AA28: S | AB28: 40639 | AC28: S | AD28: R$ 205.046.507,00 | AE28: S | AF28: N | AG28: N | AH28: S | AI28: 33000 | AJ28: 757 | AK28: CALZEDONIA BRASIL COMERCIO DE MODA E ACESSORIOS LTDA | AL28: S | AM28: S | AN28: D | AO28: N/D | AP28: N/D | AR28: Liberado | AS28: 46150 | AT28: =Calculo!AQ28 -> 47 | AU28: =Calculo!AV28 -> SEM-RISCO | AV28: =Calculo!AW28 -> LIBERADO | AW28: =Calculo!AX28 -> N/A | AX28: =Calculo!K28 -> N/A | AY28: =Calculo!AY28 -> N/A | AZ28: =Calculo!AZ28 -> N/A
A29: ='Parâmetros'!$A$19 -> Rel. Básico PJ | B29: 488 | C29: 25183 | D29: Oaco | E29: 144513 | F29: 614 | G29: OK | H29: S | I29: N | J29: N | K29: N | L29: N | M29: S | N29: RS | O29: - | P29: S | Q29: 100 | R29: N | S29: S | T29: S | U29: S | V29: S | W29: N | X29: S | Y29: N | Z29: N | AA29: S | AB29: 40639 | AC29: S | AD29: R$ 205.046.507,00 | AE29: S | AF29: N | AG29: N | AH29: S | AI29: 33000 | AJ29: 757 | AK29: CALZEDONIA BRASIL COMERCIO DE MODA E ACESSORIOS LTDA | AL29: S | AM29: S | AN29: D | AO29: N/D | AP29: N/D | AR29: Liberado | AS29: 46150 | AT29: =Calculo!AQ29 -> 47 | AU29: =Calculo!AV29 -> SEM-RISCO | AV29: =Calculo!AW29 -> LIBERADO | AW29: =Calculo!AX29 -> N/A | AX29: =Calculo!K29 -> N/A | AY29: =Calculo!AY29 -> N/A | AZ29: =Calculo!AZ29 -> N/A
A30: ='Parâmetros'!$A$19 -> Rel. Básico PJ | B30: 496 | C30: 25286 | D30: Oaco | E30: 144520 | F30: 614 | G30: OK | H30: S | I30: N | J30: N | K30: N | L30: N | M30: S | N30: RS | O30: - | P30: S | Q30: 100 | R30: N | S30: S | T30: S | U30: S | V30: S | W30: N | X30: S | Y30: N | Z30: N | AA30: S | AB30: 40639 | AC30: S | AD30: R$ 205.046.507,00 | AE30: S | AF30: N | AG30: N | AH30: S | AI30: 33000 | AJ30: 757 | AK30: CALZEDONIA BRASIL COMERCIO DE MODA E ACESSORIOS LTDA | AL30: S | AM30: S | AN30: D | AO30: N/D | AP30: N/D | AR30: Liberado | AS30: 46153 | AT30: =Calculo!AQ30 -> 47 | AU30: =Calculo!AV30 -> SEM-RISCO | AV30: =Calculo!AW30 -> LIBERADO | AW30: =Calculo!AX30 -> N/A | AX30: =Calculo!K30 -> N/A | AY30: =Calculo!AY30 -> N/A | AZ30: =Calculo!AZ30 -> N/A
A31: ='Parâmetros'!$A$19 -> Rel. Básico PJ | B31: 499 | C31: 24507 | D31: Oaco | E31: 029288 | F31: 20400 | G31: OK | H31: S | I31: N | J31: N | K31: N | L31: S | M31: S | N31: SP | O31: - | P31: S | Q31: 100 | R31: N | S31: N | T31: N | U31: S | V31: S | W31: N | X31: S | Y31: S | Z31: N | AA31: S | AB31: 36426 | AC31: N | AE31: S | AF31: N | AG31: N | AH31: N | AI31: 0 | AJ31: 826 | AK31: COOPERATIVA VEILING HOLAMBRA | AL31: S | AM31: S | AN31: D | AO31: N/D | AP31: N/D | AR31: Liberado | AS31: 46153 | AT31: =Calculo!AQ31 -> 26 | AU31: =Calculo!AV31 -> SEM-RISCO | AV31: =Calculo!AW31 -> LIBERADO | AW31: =Calculo!AX31 -> SOLICITAR PED COMPRA | AX31: =Calculo!K31 -> SOLIC CONTRATO DE ENTREGA | AY31: =Calculo!AY31 -> N/A | AZ31: =Calculo!AZ31 -> N/A
A32: ='Parâmetros'!$A$19 -> Rel. Básico PJ | B32: 194 | C32: 24655 | D32: Metalpleno | E32: 027081 | F32: 3730.8 | G32: OK | H32: S | I32: N | J32: N | K32: N | L32: S | M32: N | N32: MG | O32: 0 | P32: S | Q32: 100 | R32: N | S32: S | T32: N | U32: S | V32: S | W32: N | X32: S | Y32: S | Z32: N | AA32: S | AB32: 36088 | AC32: S | AD32: R$ 56.186.394,00 | AE32: S | AF32: S | AG32: N | AH32: S | AI32: 54894.55 | AJ32: 641 | AK32: CIMED INDUSTRIA SA | AL32: S | AM32: S | AN32: D | AO32: N/D | AP32: N/D | AR32: Liberado | AS32: 46154 | AT32: =Calculo!AQ32 -> 17 | AU32: =Calculo!AV32 -> SEM-RISCO | AV32: =Calculo!AW32 -> LIBERADO | AW32: =Calculo!AX32 -> N/A | AX32: =Calculo!K32 -> SOLIC CONTRATO DE ENTREGA | AY32: =Calculo!AY32 -> CHECAGEM REVERSA | AZ32: =Calculo!AZ32 -> N/A
A33: ='Parâmetros'!$A$19 -> Rel. Básico PJ | B33: 507 | C33: 25335 | D33: Oaco | E33: 143764 | F33: 2320 | G33: OK | H33: S | I33: N | J33: N | K33: N | L33: S | M33: S | N33: DF | O33: - | P33: S | Q33: 100 | R33: N | S33: S | T33: N | U33: S | V33: S | W33: S | X33: S | Y33: S | Z33: N | AA33: S | AB33: 30568 | AC33: N | AE33: S | AF33: N | AG33: N | AH33: N | AI33: 0 | AJ33: 596 | AK33: CONSELHO NACIONAL DE SECRETARIOS DE SAUDE | AL33: S | AM33: S | AN33: D | AO33: N/D | AP33: N/D | AR33: Liberado | AS33: 46154 | AT33: =Calculo!AQ33 -> 32 | AU33: =Calculo!AV33 -> SEM-RISCO | AV33: =Calculo!AW33 -> LIBERADO | AW33: =Calculo!AX33 -> N/A | AX33: =Calculo!K33 -> SOLIC CONTRATO DE ENTREGA | AY33: =Calculo!AY33 -> N/A | AZ33: =Calculo!AZ33 -> N/A
A34: ='Parâmetros'!$A$19 -> Rel. Básico PJ | B34: 511 | C34: 25318 | D34: Oaco | E34: 144527 | F34: 4350 | G34: OK | H34: S | I34: N | J34: N | K34: N | L34: S | M34: S | N34: RJ | O34: 5 | P34: S | Q34: 100 | R34: N | S34: N | T34: N | U34: S | V34: S | W34: N | X34: S | Y34: S | Z34: N | AA34: S | AB34: 26156 | AC34: N | AD34: R$ 844.613.653,86 | AE34: S | AF34: S | AG34: N | AH34: S | AI34: 3607770.8 | AJ34: 757 | AK34: COMPANHIA ESTADUAL DE AGUAS E ESGOTO CEDAE | AL34: S | AM34: S | AN34: D | AO34: N/D | AP34: N/D | AR34: Liberado | AS34: 46155 | AT34: =Calculo!AQ34 -> 7 | AU34: =Calculo!AV34 -> SEM-RISCO | AV34: =Calculo!AW34 -> LIBERADO | AW34: =Calculo!AX34 -> N/A | AX34: =Calculo!K34 -> SOLIC CONTRATO DE ENTREGA | AY34: =Calculo!AY34 -> N/A | AZ34: =Calculo!AZ34 -> N/A
A35: ='Parâmetros'!$A$19 -> Rel. Básico PJ | B35: 210 | C35: 25339 | D35: Metalpleno | E35: 144552 | F35: 14810 | G35: OK | H35: S | I35: N | J35: N | K35: N | L35: S | M35: S | N35: SC | O35: 5 | P35: S | Q35: 100 | R35: N | S35: N | T35: N | U35: S | V35: S | W35: N | X35: S | Y35: N | Z35: N | AA35: S | AB35: 39093 | AC35: N | AD35: R$ 68.805.136,00 | AE35: S | AF35: N | AG35: N | AH35: N | AI35: 0 | AJ35: 978 | AK35: BOM JARDIM ENERGIA EOLICA SA | AL35: S | AM35: S | AN35: D | AO35: N/D | AP35: N/D | AR35: Liberado | AS35: 46164 | AT35: =Calculo!AQ35 -> 39 | AU35: =Calculo!AV35 -> SEM-RISCO | AV35: =Calculo!AW35 -> LIBERADO | AW35: =Calculo!AX35 -> SOLICITAR PED COMPRA | AX35: =Calculo!K35 -> SOLIC CONTRATO DE ENTREGA | AY35: =Calculo!AY35 -> N/A | AZ35: =Calculo!AZ35 -> N/A
A36: ='Parâmetros'!$A$19 -> Rel. Básico PJ | B36: 211 | C36: 25340 | D36: Metalpleno | E36: 141469 | F36: 15232 | G36: OK | H36: S | I36: N | J36: N | K36: N | L36: S | M36: S | N36: SC | O36: 5 | P36: S | Q36: 100 | R36: N | S36: N | T36: N | U36: S | V36: S | W36: N | X36: S | Y36: N | Z36: N | AA36: S | AB36: 39093 | AC36: N | AD36: R$ 67.599.702,00 | AE36: S | AF36: N | AG36: N | AH36: N | AI36: 0 | AJ36: 703 | AK36: AQUIBATA ENERGIA EOLICA SA | AL36: S | AM36: S | AN36: D | AO36: N/D | AP36: N/D | AR36: Liberado | AS36: 46164 | AT36: =Calculo!AQ36 -> 39 | AU36: =Calculo!AV36 -> SEM-RISCO | AV36: =Calculo!AW36 -> LIBERADO | AW36: =Calculo!AX36 -> SOLICITAR PED COMPRA | AX36: =Calculo!K36 -> SOLIC CONTRATO DE ENTREGA | AY36: =Calculo!AY36 -> N/A | AZ36: =Calculo!AZ36 -> N/A
A37: ='Parâmetros'!$A$19 -> Rel. Básico PJ | B37: 195 | C37: 25207 | D37: Metalpleno | E37: 144528 | F37: 13704 | G37: OK | H37: S | I37: N | J37: N | K37: N | L37: S | M37: S | N37: SP | O37: 5 | P37: S | Q37: 100 | R37: N | S37: N | T37: N | U37: S | V37: S | W37: N | X37: S | Y37: S | Z37: N | AA37: S | AB37: 29619 | AC37: N | AD37: R$ 34.403.499,00 | AE37: S | AF37: S | AG37: N | AH37: N | AI37: 70.37 | AJ37: 906 | AK37: TRUMPF MAQUINAS INDUSTRIA E COMERCIO LTDA | AL37: S | AM37: S | AN37: D | AO37: N/D | AP37: N/D | AR37: Liberado | AS37: 46155 | AT37: =Calculo!AQ37 -> 44 | AU37: =Calculo!AV37 -> SEM-RISCO | AV37: =Calculo!AW37 -> LIBERADO | AW37: =Calculo!AX37 -> SOLICITAR PED COMPRA | AX37: =Calculo!K37 -> SOLIC CONTRATO DE ENTREGA | AY37: =Calculo!AY37 -> N/A | AZ37: =Calculo!AZ37 -> N/A
A38: ='Parâmetros'!$A$19 -> Rel. Básico PJ | B38: 196 | C38: 25348 | D38: Metalpleno | E38: 144306 | F38: 7030 | G38: OK | H38: S | I38: N | J38: N | K38: N | L38: S | M38: S | N38: SP | O38: 5 | P38: S | Q38: 100 | R38: N | S38: S | T38: S | U38: S | V38: S | W38: N | X38: S | Y38: N | Z38: N | AA38: S | AB38: 26835 | AC38: S | AE38: S | AF38: S | AG38: N | AH38: N | AI38: 6000.01 | AJ38: 799 | AK38: UNIMED DE ARARAQUARA COOPERATIVA DE TRABALHO MEDICO | AL38: S | AM38: S | AN38: D | AO38: N/D | AP38: N/D | AR38: Liberado | AS38: 46155 | AT38: =Calculo!AQ38 -> 60 | AU38: =Calculo!AV38 -> SEM-RISCO | AV38: =Calculo!AW38 -> LIBERADO | AW38: =Calculo!AX38 -> SOLICITAR PED COMPRA | AX38: =Calculo!K38 -> SOLIC CONTRATO DE ENTREGA | AY38: =Calculo!AY38 -> N/A | AZ38: =Calculo!AZ38 -> N/A
A39: ='Parâmetros'!$A$19 -> Rel. Básico PJ | B39: 197 | C39: 25303 | D39: Metalpleno | E39: 144199 | F39: 6402 | G39: OK | H39: S | I39: N | J39: N | K39: N | L39: S | M39: N | N39: SP | O39: 0 | P39: S | Q39: 100 | R39: N | S39: S | T39: N | U39: S | V39: S | W39: N | X39: S | Y39: S | Z39: N | AA39: S | AB39: 43796 | AC39: N | AD39: R$ 823.920.411,76 | AE39: S | AF39: N | AG39: N | AH39: N | AI39: 0 | AJ39: 739 | AK39: LINS AGROINDUSTRIAL SA | AL39: S | AM39: S | AN39: D | AO39: N/D | AP39: N/D | AR39: Liberado | AS39: 46156 | AT39: =Calculo!AQ39 -> 43 | AU39: =Calculo!AV39 -> SEM-RISCO | AV39: =Calculo!AW39 -> LIBERADO | AW39: =Calculo!AX39 -> SOLICITAR PED COMPRA | AX39: =Calculo!K39 -> SOLIC CONTRATO DE ENTREGA | AY39: =Calculo!AY39 -> CHECAGEM REVERSA | AZ39: =Calculo!AZ39 -> N/A
A40: ='Parâmetros'!$A$19 -> Rel. Básico PJ | B40: 198 | C40: 24639 | D40: Metalpleno | E40: 143127 | F40: 6402 | G40: OK | H40: S | I40: S | J40: N | K40: N | L40: S | M40: N | N40: SP | O40: 0 | P40: S | Q40: 100 | R40: N | S40: S | T40: N | U40: S | V40: S | W40: N | X40: S | Y40: N | Z40: N | AA40: S | AB40: 44090 | AC40: N | AD40: R$ 2.000,00 | AE40: S | AF40: N | AG40: N | AH40: N | AI40: 0 | AJ40: 757 | AK40: JHV IMPORTACAO , EXPORTACAO INDUSTRIA E COMERCIO LTDA | AL40: S | AM40: N | AN40: D | AO40: N/D | AP40: N/D | AR40: Liberado | AS40: 46156 | AT40: =Calculo!AQ40 -> 42 | AU40: =Calculo!AV40 -> SEM-RISCO | AV40: =Calculo!AW40 -> LIBERADO | AW40: =Calculo!AX40 -> SOLICITAR PED COMPRA | AX40: =Calculo!K40 -> SOLIC CONTRATO DE ENTREGA | AY40: =Calculo!AY40 -> CHECAGEM REVERSA | AZ40: =Calculo!AZ40 -> N/A
...

Sheet AJUDA
A1: 1414 | B1: Se for antecipado ou simples faturamento para recebermos antes de despachar, não precisa fazer análise. Se for pedido de revendedor que compra direto, não precisa fazer a consulta e preencher a planilha. Só bloqueie se tiver pagamentos em atraso. Coloca no follow: Cliente revenda conhecida, liberado sem análise.
A2: Consulta | B2: https://web2.bvsnet.com.br/transacional/login.php Login: AC098902 | BW@2022 .... > Pessoa Jurídica > Outros Produtos para Crédito > Define Risco (Imagem======================================================>>>
A3: PED | B3: Número do pedido do Protheus | C3: AC098902
A4: 2-Empresa | B4: Nossa empresa: BN, S4T, OW ou GS
A5: 3-Cliente | B5: Código do Cliente
A6: 4-Total Ped. R$ | B6: Total do pedido com frete e tudo. Valor que aparece no pedido
A7: Desconto Ped | B7: Verificar se o vendedor respeitou o limite. Máx: 3% Faturado ou 6% antecipado. Dar um F3 em cima do código do produto. Revenda tem 10% de desconto.
A8: 5-Faturado | B8: S | N - Se tiver algum pagamento depois de despacharmos o produto.
A9: 6-Entrada | B9: S | N - Se tiver algum BA ou depósito antecipado.
A10: 7-Quant. Grande? | B10: S | N - Se tiver + DE 10 Cofres, + DE 5 Armário Corta Fogo, + DE 5 Fragmentadoras ou acima de 30 pacotes/rolos de suprimentos
A11: 8-Prod. Q Ñ Combinam? | B11: S = sim tem ptrodutos que não combinam | N - não tem produto que não combinam. Exemplo: o cliente compra fragmentadoras e cofres.
A12: Armário ou Cofre > 2.000 | B12: S | N - Se tem algum produto que exija contrato de entrega.
A13: Entrega=Cadastro | B13: S | N - Se for CLIENTE RETIRA = N | Se constar endereço de entrega diferente na Obs da NF = N | Se não houver nenhuma informação na Mensagem pra Nota informando local diferente = S
A14: UF do Cliente | B14: Preencher com a sigla do estado dele, exemplo: RJ ou SP ou PB... (sempre 2 letras MAIÚSCULAS).
A15: Google Maps 0|5|10 | B15: 0 | 5 | 10 - Se for CLIENTE RETIRA = 0 | Usar o endereço de entrega. Se não tiver end. de entrega usar o do cadastro mesmo. Se for um local ruim, 0, se for razoável 5 e se for um lugar muito bom 10, se não localizar coloca um TRAÇO -
... A32: 25-SalvarPDFConsltRede | B32: Fazer a consulta no Boa Vista e salva a consulta na rede dentro de G:\Drives compartilhados\Financeiro Consulta\Consultas salve com o nome da empresa sem / e se for repetido, coloque a data no final 2021-04-30
A33: 24-PFIN | B33: S | N - Na consulta Boa Vista mostra (em 23.06.2023 CONSULTAMOS ATUALMENTE PELO SERASA. LOGON É=76582187 E SENHA É=Bwe@2022 )https://empresas.serasaexperian.com.br/meus-produtos/login | C33: https://web2.bvsnet.com.br/transacional/login.php
A34: 23-Ch s/ Fundo | B34: S | N - Na consulta Boa Vista mostra | C34: AC098902
A35: 21-Protestos | B35: S | N - Na consulta Boa Vista mostra
A36: 22-Vlr Prot. | B36: Coloca o valor total dos protestos em R$
A37: 28 - SCORE Serasa | B37: Coloca o Score que a consulta do Serasa dá. Se aparecer Default coloca 0.
A38: Nome que consta na REGULARIDADE DO FGTS | B38: Cole o nome que aparece no site - Acesse o site https://consulta-crf.caixa.gov.br/consultacrf/pages/consultaEmpregador.jsf > Coloque o CNPJ sem números e preencha o Captcha.
A39: Situação Regular? | B39: S | N - Se constar: "A EMPRESA abaixo identificada está REGULAR" = S. Mas se constar: "As informações disponíveis não são suficientes para a comprovação..." = N "EMPREGADOR NÃO CADASTRADO" = N
A40: 33-RAZÃO E FGTS IGUAL?S/N | B40: S | N - O nome que aparece está igual ao do cadastro do Protheus?
A41: 34-Certid Trib Federais | B41: S (Sim emitiu e não constam debitos | N (Não foi possível emitir) | D (Emitiu mas constam Débitos)- http://servicos.receita.fazenda.gov.br/Servicos/certidaointernet/PJ/Emitir
A42: 30-3 NF Conf. | B42: Use em caso de cliente que está próximo ao score 0 ou que vc desconfie que é golpe. Solicite uma Nfe recente de valor igual ou maior ao pedido que ele esta fazendo.
A43: 31 - Conta de Luz | B43: Use em caso que vc desconfie que é golpe. Solicite uma conta recente de luz do endereço de entrega. Se for apresentdo uma conta com valor baixo = golpe.
A44: OBS | B44: Coloque aqui por exemplo: Pedi uma Nf, liberado só se... avisei o vendedor..., etc
A45: Final: Lib/Entrada/Bloqu. só AV | B45: Coloque: Liberado | Entrada | Bloqueado onde Liberado OK, Entrada é só com entrada e Bloqueado é quando o cadastro é ruim mesmo.
A46: Data | B46: Data de hoje
A47: Total Score | B47: Automático. Menor que 0 = Bloqueia ou pede entrada ou antecipado ou sugere link de pagamento. De 1 a 5 = Pede uma NF ou conta de luz. De 6 acima liberado. Cola as celulas amarelas no follow do pedido.
A48: Risco
A49: Sugestão | B49: A planilha vai lhe dizer o que ela acha.
A50: Obs: | B50: Ela vai lhe avise se é necessário pedir o PC pelo valor do pedido.
A51: Contratato Entrega | B51: Ela vai lhe avisar se é pra pedir Contrato de Entrega.
A53: Ao terminar as análises, dá uma olhada em pedidos antigos e tenta empurrar, cobrando contratos de entregas, PC, depósitos e etc.
A54: Tela de análise, seleciona o pedido e sempre clica em Manual:
A65: Se o pedido vai ficar parado na análise, pois estamos esperando algo ou alguma resposta clica em Cancelar.
A66: Se o pedido não passou e não tem jeito, clica em Rejeitar
A67: Se o pedido passou na análise, clica em Lib. Todos.
...

Sheet Calculo
A1: =Consultas!A1 -> Tipo | B1: PED | C1: 2-Empresa | D1: 3-Cliente | E1: 19-Idade | F1: 4-Total Ped. R$ | G1: 5-Faturado | H1: 6-Entrada | I1: 7-Muitos Itens | J1: 8-Prod. Variados | K1: Armário ou Cofre > 1800 | L1: 9-Pgtos Abertos | M1: 10-Já Comprou e Pagou 2X ou +? | N1: 10-Comprou e pagou +5X? | O1: 11-Cadastro=Receita | P1: 12-CNPJ Ativo | Q1: 13-Entrega=Cadastro | R1: UF do Cliente | S1: Google Maps 0|5|10 | T1: Registro.Br | U1: ScamAdvizer | V1: 14-Casa/Sala/Conj no end. | W1: EmailSiteReceita=@corporativo? | X1: Existe Mail Financeiro Diferente? | Y1: 15-Mail gratuito | Z1: 16-Possui Site | AA1: 18-Fundação Matriz | AB1: 19-IdadeScore | AC1: 20-MUITO Grande /Conhecida | AD1: 21-Protestos | AE1: 22-Vlr Prot. | AF1: 22-Prot.XCapit | AG1: 23-Ch s/ Fundo | AH1: 24-Pend. Fin. | AI1: 28 - SCORE Serasa | AJ1: 29-Capital Soc. | AK1: 30-3 Boletos Conf. | AL1: 31-Ref. Comercial | AM1: Situação Regular? | AN1: 33-RAZÃO E FGTS IGUAL?S/N | AO1: 34-Certid Trib Mobiliaros | AQ1: Total Score | AR1: EMPRESINHA | AS1: GOLPE | AT1: GRANDE-FALINDO | AU1: Menor Valor | AV1: Risco | AW1: Sugestão | AX1: Obs | AY1: Retira e Faturado | AZ1: Cadastro = Receita
A2: Define Risco | B2: =Consultas!B2 -> 162 | C2: =Consultas!D2 -> Metalpleno | D2: =Consultas!E2 -> 034331 | E2: =IF(Consultas!AB2>0,YEAR('Parâmetros'!$B$1)-YEAR(Consultas!AB2),"NA") -> 31 | F2: =IF(Consultas!F2>'Parâmetros'!$B$2,-8,0) -> 0 | G2: =IF(Consultas!H2='Parâmetros'!$E$1,100,0) -> 0 | H2: =IF(Consultas!I2='Parâmetros'!$E$1,-4,12) -> -4 | I2: =IF(Consultas!J2='Parâmetros'!$E$1,1,-13) -> 1 | J2: =IF(Consultas!K2='Parâmetros'!$E$1,2,-5) -> 2 | K2: =IF(Consultas!L2='Parâmetros'!$D$1,"SOLIC CONTRATO DE ENTREGA","N/A") -> SOLIC CONTRATO DE ENTREGA | L2: =IF(Consultas!R2='Parâmetros'!$E$1,1,-3) -> 1 | M2: =IF(Consultas!S2>1,(IF(Consultas!S2='Parâmetros'!$E$1,-3,9))) -> 9 | N2: =IF(Consultas!T2="S",23,0) -> 0 | O2: =IF(Consultas!U2='Parâmetros'!$E$1,-3,3) -> 3 | P2: =IF(Consultas!V2='Parâmetros'!$E$1,-100,2) -> 2 | Q2: =IF(Consultas!M2='Parâmetros'!$D$1,2,-9) -> -9 | R2: =IF(Consultas!N2="RJ",-12,0) -> 0 | S2: =IF(Consultas!O2="-",-3,IF(Consultas!O2=0,-6,IF(Consultas!O2=5,0,IF(Consultas!O2=10,6)))) -> -6 | T2: =IF(Consultas!M2="S",0,(IF(Consultas!P2="S",6,0))) -> 0 | U2: =IF(Consultas!Q2>97,9,IF(Consultas!Q2>75,0,-7)) -> 9 | V2: =IF(Consultas!W2='Parâmetros'!$E$1,1,-5) -> 1 | W2: =IF(Consultas!X2="S",3,-3) -> 3 | X2: =IF(Consultas!Y2="S",0,-7) -> 0 | Y2: =IF(Consultas!Z2='Parâmetros'!$E$1,2,-8) -> 2 | Z2: =IF(Consultas!AA2='Parâmetros'!$E$1,-15,1) -> 1 | AA2: - | AB2: =IF(E2="NA","NA",IF(E2>'Parâmetros'!$A$9,8,IF(E2>'Parâmetros'!$A$8,4,IF(E2>'Parâmetros'!$A$7,0,-6)))) -> 8 | AC2: =IF(Consultas!AC2='Parâmetros'!$E$1,0,5) -> 0 | AD2: =IF(Consultas!AH2='Parâmetros'!$D$1,-10,5) -> 5 | AE2: =IF(Consultas!AI2>(Consultas!F2*2),-10,0) -> 0 | AF2: =IF(Consultas!AD2>1,(IF(Consultas!AI2>(Consultas!AD2),-20,4))) -> 4 | AG2: =IF(Consultas!AG2='Parâmetros'!$E$1,0,-6) -> 0 | AH2: =IF(Consultas!AF2='Parâmetros'!$E$1,1,-5) -> 1 | AI2: =IF(Consultas!AJ2>700,8,IF(Consultas!AJ2>500,4,IF(Consultas!AJ2>200,-4,IF(Consultas!AJ2>1,-15,-20)))) -> 8 | AJ2: =IF(Consultas!AD2='Parâmetros'!$E$10,0,IF(Consultas!AD2>'Parâmetros'!$A$30,12,IF(Consultas!AD2>'Parâmetros'!$A$31,6,IF(Consultas!AD2>'Parâmetros'!$A$32,0,IF(Consultas!AD2>'Parâmetros'!$A$33,0,IF(Consultas!AD2>'Parâmetros'!$A$34,-3,IF(Consultas!AD2>'Parâmetros'!$A$35,-7,-1))))))) -> 12 | AK2: =IF(Consultas!AO2='Parâmetros'!$D$1,3,-3) -> -3 | AL2: =IF(Consultas!AP2='Parâmetros'!$D$1,5,-3) -> -3 | AM2: =IF(Consultas!AL2="N",-6,0) -> 0 | AN2: =IF(Consultas!AM2="N",-10,0) -> 0 | AO2: =IF(Consultas!AN2="S",4,-2) -> -2 | AQ2: =IF(Consultas!F2>1,(SUM(F2:AO2)),"N/A") -> 45 | AR2: =IF((Consultas!AD2>'Parâmetros'!$A$31),"X",AJ2+Y2+V2+AC2) -> X | AS2: =IF((Consultas!AD2>'Parâmetros'!$A$31),"X",(H2+I2+J2+Q2+T2+Y2+Z2+AJ2+AN2)) -> X | AT2: =IF((Consultas!AD2<'Parâmetros'!$A$31),"X",(AD2+AC2+AB2)) -> 13 | AU2: =SMALL(AR2:AT2,1) -> 13 | AV2: =IF(AQ2="N/A","N/A",IF(AQ2>5,'Parâmetros'!$A$15,(IF(AU2=AR2,'Parâmetros'!$A$17,IF(AU2=AS2,'Parâmetros'!$A$16,'Parâmetros'!$A$14))))) -> SEM-RISCO | AW2: =IF(AQ2="N/A","N/A",IF(AV2='Parâmetros'!$A$15,'Parâmetros'!$C$15,(IF(AV2='Parâmetros'!$A$17,'Parâmetros'!$C$17,IF(AV2='Parâmetros'!$A$16,'Parâmetros'!$C$16,IF(AV2='Parâmetros'!$A$14,'Parâmetros'!$C$12)))))) -> LIBERADO | AX2: =IF(Consultas!F2>1,(IF(Consultas!F2>5000,"SOLICITAR PED COMPRA","N/A"))) -> SOLICITAR PED COMPRA | AY2: =IF(AND(Consultas!M2<>"S", Consultas!H2="S"), "CHECAGEM REVERSA", "N/A") -> CHECAGEM REVERSA | AZ2: =IF(Consultas!U2="N","PRECISA CORRIGIR END DIVERGENTE","N/A") -> N/A
A3: Define Risco | B3: =Consultas!B3 -> 166 | C3: =Consultas!D3 -> Metalpleno | D3: =Consultas!E3 -> 141660 | E3: =IF(Consultas!AB3>0,YEAR('Parâmetros'!$B$1)-YEAR(Consultas!AB3),"NA") -> 60 | F3: =IF(Consultas!F3>'Parâmetros'!$B$2,-8,0) -> 0 | G3: =IF(Consultas!H3='Parâmetros'!$E$1,100,0) -> 0 | H3: =IF(Consultas!I3='Parâmetros'!$E$1,-4,12) -> 12 | I3: =IF(Consultas!J3='Parâmetros'!$E$1,1,-13) -> 1 | J3: =IF(Consultas!K3='Parâmetros'!$E$1,2,-5) -> 2 | K3: =IF(Consultas!L3='Parâmetros'!$D$1,"SOLIC CONTRATO DE ENTREGA","N/A") -> SOLIC CONTRATO DE ENTREGA | L3: =IF(Consultas!R3='Parâmetros'!$E$1,1,-3) -> 1 | M3: =IF(Consultas!S3>1,(IF(Consultas!S3='Parâmetros'!$E$1,-3,9))) -> -3 | N3: =IF(Consultas!T3="S",23,0) -> 0 | O3: =IF(Consultas!U3='Parâmetros'!$E$1,-3,3) -> 3 | P3: =IF(Consultas!V3='Parâmetros'!$E$1,-100,2) -> 2 | Q3: =IF(Consultas!M3='Parâmetros'!$D$1,2,-9) -> 2 | R3: =IF(Consultas!N3="RJ",-12,0) -> 0 | S3: =IF(Consultas!O3="-",-3,IF(Consultas!O3=0,-6,IF(Consultas!O3=5,0,IF(Consultas!O3=10,6)))) -> 0 | T3: =IF(Consultas!M3="S",0,(IF(Consultas!P3="S",6,0))) -> 0 | U3: =IF(Consultas!Q3>97,9,IF(Consultas!Q3>75,0,-7)) -> 9 | V3: =IF(Consultas!W3='Parâmetros'!$E$1,1,-5) -> 1 | W3: =IF(Consultas!X3="S",3,-3) -> 3 | X3: =IF(Consultas!Y3="S",0,-7) -> 0 | Y3: =IF(Consultas!Z3='Parâmetros'!$E$1,2,-8) -> 2 | Z3: =IF(Consultas!AA3='Parâmetros'!$E$1,-15,1) -> 1 | AA3: - | AB3: =IF(E3="NA","NA",IF(E3>'Parâmetros'!$A$9,8,IF(E3>'Parâmetros'!$A$8,4,IF(E3>'Parâmetros'!$A$7,0,-6)))) -> 8 | AC3: =IF(Consultas!AC3='Parâmetros'!$E$1,0,5) -> 0 | AD3: =IF(Consultas!AH3='Parâmetros'!$D$1,-10,5) -> 5 | AE3: =IF(Consultas!AI3>(Consultas!F3*2),-10,0) -> 0 | AF3: =IF(Consultas!AD3>1,(IF(Consultas!AI3>(Consultas!AD3),-20,4))) -> 4 | AG3: =IF(Consultas!AG3='Parâmetros'!$E$1,0,-6) -> 0 | AH3: =IF(Consultas!AF3='Parâmetros'!$E$1,1,-5) -> -5 | AI3: =IF(Consultas!AJ3>700,8,IF(Consultas!AJ3>500,4,IF(Consultas!AJ3>200,-4,IF(Consultas!AJ3>1,-15,-20)))) -> 4 | AJ3: =IF(Consultas!AD3='Parâmetros'!$E$10,0,IF(Consultas!AD3>'Parâmetros'!$A$30,12,IF(Consultas!AD3>'Parâmetros'!$A$31,6,IF(Consultas!AD3>'Parâmetros'!$A$32,0,IF(Consultas!AD3>'Parâmetros'!$A$33,0,IF(Consultas!AD3>'Parâmetros'!$A$34,-3,IF(Consultas!AD3>'Parâmetros'!$A$35,-7,-1))))))) -> 12 | AK3: =IF(Consultas!AO3='Parâmetros'!$D$1,3,-3) -> -3 | AL3: =IF(Consultas!AP3='Parâmetros'!$D$1,5,-3) -> -3 | AM3: =IF(Consultas!AL3="N",-6,0) -> 0 | AN3: =IF(Consultas!AM3="N",-10,0) -> 0 | AO3: =IF(Consultas!AN3="S",4,-2) -> -2 | AQ3: =IF(Consultas!F3>1,(SUM(F3:AO3)),"N/A") -> 56 | AR3: =IF((Consultas!AD3>'Parâmetros'!$A$31),"X",AJ3+Y3+V3+AC3) -> X | AS3: =IF((Consultas!AD3>'Parâmetros'!$A$31),"X",(H3+I3+J3+Q3+T3+Y3+Z3+AJ3+AN3)) -> X | AT3: =IF((Consultas!AD3<'Parâmetros'!$A$31),"X",(AD3+AC3+AB3)) -> 13 | AU3: =SMALL(AR3:AT3,1) -> 13 | AV3: =IF(AQ3="N/A","N/A",IF(AQ3>5,'Parâmetros'!$A$15,(IF(AU3=AR3,'Parâmetros'!$A$17,IF(AU3=AS3,'Parâmetros'!$A$16,'Parâmetros'!$A$14))))) -> SEM-RISCO | AW3: =IF(AQ3="N/A","N/A",IF(AV3='Parâmetros'!$A$15,'Parâmetros'!$C$15,(IF(AV3='Parâmetros'!$A$17,'Parâmetros'!$C$17,IF(AV3='Parâmetros'!$A$16,'Parâmetros'!$C$16,IF(AV3='Parâmetros'!$A$14,'Parâmetros'!$C$12)))))) -> LIBERADO | AX3: =IF(Consultas!F3>1,(IF(Consultas!F3>5000,"SOLICITAR PED COMPRA","N/A"))) -> SOLICITAR PED COMPRA | AY3: =IF(AND(Consultas!M3<>"S", Consultas!H3="S"), "CHECAGEM REVERSA", "N/A") -> N/A | AZ3: =IF(Consultas!U3="N","PRECISA CORRIGIR END DIVERGENTE","N/A") -> N/A
A4: Define Risco | B4: =Consultas!B4 -> 167 | C4: =Consultas!D4 -> Metalpleno | D4: =Consultas!E4 -> 144468 | E4: =IF(Consultas!AB4>0,YEAR('Parâmetros'!$B$1)-YEAR(Consultas!AB4),"NA") -> 21 | F4: =IF(Consultas!F4>'Parâmetros'!$B$2,-8,0) -> 0 | G4: =IF(Consultas!H4='Parâmetros'!$E$1,100,0) -> 0 | H4: =IF(Consultas!I4='Parâmetros'!$E$1,-4,12) -> 12 | I4: =IF(Consultas!J4='Parâmetros'!$E$1,1,-13) -> 1 | J4: =IF(Consultas!K4='Parâmetros'!$E$1,2,-5) -> 2 | K4: =IF(Consultas!L4='Parâmetros'!$D$1,"SOLIC CONTRATO DE ENTREGA","N/A") -> SOLIC CONTRATO DE ENTREGA | L4: =IF(Consultas!R4='Parâmetros'!$E$1,1,-3) -> 1 | M4: =IF(Consultas!S4>1,(IF(Consultas!S4='Parâmetros'!$E$1,-3,9))) -> -3 | N4: =IF(Consultas!T4="S",23,0) -> 0 | O4: =IF(Consultas!U4='Parâmetros'!$E$1,-3,3) -> 3 | P4: =IF(Consultas!V4='Parâmetros'!$E$1,-100,2) -> 2 | Q4: =IF(Consultas!M4='Parâmetros'!$D$1,2,-9) -> 2 | R4: =IF(Consultas!N4="RJ",-12,0) -> 0 | S4: =IF(Consultas!O4="-",-3,IF(Consultas!O4=0,-6,IF(Consultas!O4=5,0,IF(Consultas!O4=10,6)))) -> 0 | T4: =IF(Consultas!M4="S",0,(IF(Consultas!P4="S",6,0))) -> 0 | U4: =IF(Consultas!Q4>97,9,IF(Consultas!Q4>75,0,-7)) -> 9 | V4: =IF(Consultas!W4='Parâmetros'!$E$1,1,-5) -> -5 | W4: =IF(Consultas!X4="S",3,-3) -> 3 | X4: =IF(Consultas!Y4="S",0,-7) -> -7 | Y4: =IF(Consultas!Z4='Parâmetros'!$E$1,2,-8) -> 2 | Z4: =IF(Consultas!AA4='Parâmetros'!$E$1,-15,1) -> 1 | AA4: - | AB4: =IF(E4="NA","NA",IF(E4>'Parâmetros'!$A$9,8,IF(E4>'Parâmetros'!$A$8,4,IF(E4>'Parâmetros'!$A$7,0,-6)))) -> 4 | AC4: =IF(Consultas!AC4='Parâmetros'!$E$1,0,5) -> 0 | AD4: =IF(Consultas!AH4='Parâmetros'!$D$1,-10,5) -> 5 | AE4: =IF(Consultas!AI4>(Consultas!F4*2),-10,0) -> 0 | AF4: =IF(Consultas!AD4>1,(IF(Consultas!AI4>(Consultas!AD4),-20,4))) -> 4 | AG4: =IF(Consultas!AG4='Parâmetros'!$E$1,0,-6) -> 0 | AH4: =IF(Consultas!AF4='Parâmetros'!$E$1,1,-5) -> 1 | AI4: =IF(Consultas!AJ4>700,8,IF(Consultas!AJ4>500,4,IF(Consultas!AJ4>200,-4,IF(Consultas!AJ4>1,-15,-20)))) -> 4 | AJ4: =IF(Consultas!AD4='Parâmetros'!$E$10,0,IF(Consultas!AD4>'Parâmetros'!$A$30,12,IF(Consultas!AD4>'Parâmetros'!$A$31,6,IF(Consultas!AD4>'Parâmetros'!$A$32,0,IF(Consultas!AD4>'Parâmetros'!$A$33,0,IF(Consultas!AD4>'Parâmetros'!$A$34,-3,IF(Consultas!AD4>'Parâmetros'!$A$35,-7,-1))))))) -> 12 | AK4: =IF(Consultas!AO4='Parâmetros'!$D$1,3,-3) -> -3 | AL4: =IF(Consultas!AP4='Parâmetros'!$D$1,5,-3) -> -3 | AM4: =IF(Consultas!AL4="N",-6,0) -> 0 | AN4: =IF(Consultas!AM4="N",-10,0) -> 0 | AO4: =IF(Consultas!AN4="S",4,-2) -> -2 | AQ4: =IF(Consultas!F4>1,(SUM(F4:AO4)),"N/A") -> 45 | AR4: =IF((Consultas!AD4>'Parâmetros'!$A$31),"X",AJ4+Y4+V4+AC4) -> X | AS4: =IF((Consultas!AD4>'Parâmetros'!$A$31),"X",(H4+I4+J4+Q4+T4+Y4+Z4+AJ4+AN4)) -> X | AT4: =IF((Consultas!AD4<'Parâmetros'!$A$31),"X",(AD4+AC4+AB4)) -> 9 | AU4: =SMALL(AR4:AT4,1) -> 9 | AV4: =IF(AQ4="N/A","N/A",IF(AQ4>5,'Parâmetros'!$A$15,(IF(AU4=AR4,'Parâmetros'!$A$17,IF(AU4=AS4,'Parâmetros'!$A$16,'Parâmetros'!$A$14))))) -> SEM-RISCO | AW4: =IF(AQ4="N/A","N/A",IF(AV4='Parâmetros'!$A$15,'Parâmetros'!$C$15,(IF(AV4='Parâmetros'!$A$17,'Parâmetros'!$C$17,IF(AV4='Parâmetros'!$A$16,'Parâmetros'!$C$16,IF(AV4='Parâmetros'!$A$14,'Parâmetros'!$C$12)))))) -> LIBERADO | AX4: =IF(Consultas!F4>1,(IF(Consultas!F4>5000,"SOLICITAR PED COMPRA","N/A"))) -> N/A | AY4: =IF(AND(Consultas!M4<>"S", Consultas!H4="S"), "CHECAGEM REVERSA", "N/A") -> N/A | AZ4: =IF(Consultas!U4="N","PRECISA CORRIGIR END DIVERGENTE","N/A") -> N/A
A5: Define Risco | B5: =Consultas!B5 -> 1864 | C5: =Consultas!D5 -> GsiBW | D5: =Consultas!E5 -> 021332 | E5: =IF(Consultas!AB5>0,YEAR('Parâmetros'!$B$1)-YEAR(Consultas!AB5),"NA") -> 43 | F5: =IF(Consultas!F5>'Parâmetros'!$B$2,-8,0) -> 0 | G5: =IF(Consultas!H5='Parâmetros'!$E$1,100,0) -> 0 | H5: =IF(Consultas!I5='Parâmetros'!$E$1,-4,12) -> -4 | I5: =IF(Consultas!J5='Parâmetros'!$E$1,1,-13) -> 1 | J5: =IF(Consultas!K5='Parâmetros'!$E$1,2,-5) -> 2 | K5: =IF(Consultas!L5='Parâmetros'!$D$1,"SOLIC CONTRATO DE ENTREGA","N/A") -> N/A | L5: =IF(Consultas!R5='Parâmetros'!$E$1,1,-3) -> 1 | M5: =IF(Consultas!S5>1,(IF(Consultas!S5='Parâmetros'!$E$1,-3,9))) -> 9 | N5: =IF(Consultas!T5="S",23,0) -> 0 | O5: =IF(Consultas!U5='Parâmetros'!$E$1,-3,3) -> 3 | P5: =IF(Consultas!V5='Parâmetros'!$E$1,-100,2) -> 2 | Q5: =IF(Consultas!M5='Parâmetros'!$D$1,2,-9) -> 2 | R5: =IF(Consultas!N5="RJ",-12,0) -> 0 | S5: =IF(Consultas!O5="-",-3,IF(Consultas!O5=0,-6,IF(Consultas!O5=5,0,IF(Consultas!O5=10,6)))) -> -3 | T5: =IF(Consultas!M5="S",0,(IF(Consultas!P5="S",6,0))) -> 0 | U5: =IF(Consultas!Q5>97,9,IF(Consultas!Q5>75,0,-7)) -> 9 | V5: =IF(Consultas!W5='Parâmetros'!$E$1,1,-5) -> 1 | W5: =IF(Consultas!X5="S",3,-3) -> 3 | X5: =IF(Consultas!Y5="S",0,-7) -> 0 | Y5: =IF(Consultas!Z5='Parâmetros'!$E$1,2,-8) -> 2 | Z5: =IF(Consultas!AA5='Parâmetros'!$E$1,-15,1) -> 1 | AA5: - | AB5: =IF(E5="NA","NA",IF(E5>'Parâmetros'!$A$9,8,IF(E5>'Parâmetros'!$A$8,4,IF(E5>'Parâmetros'!$A$7,0,-6)))) -> 8 | AC5: =IF(Consultas!AC5='Parâmetros'!$E$1,0,5) -> 0 | AD5: =IF(Consultas!AH5='Parâmetros'!$D$1,-10,5) -> 5 | AE5: =IF(Consultas!AI5>(Consultas!F5*2),-10,0) -> 0 | AF5: =IF(Consultas!AD5>1,(IF(Consultas!AI5>(Consultas!AD5),-20,4))) -> 4 | AG5: =IF(Consultas!AG5='Parâmetros'!$E$1,0,-6) -> 0 | AH5: =IF(Consultas!AF5='Parâmetros'!$E$1,1,-5) -> 1 | AI5: =IF(Consultas!AJ5>700,8,IF(Consultas!AJ5>500,4,IF(Consultas!AJ5>200,-4,IF(Consultas!AJ5>1,-15,-20)))) -> 8 | AJ5: =IF(Consultas!AD5='Parâmetros'!$E$10,0,IF(Consultas!AD5>'Parâmetros'!$A$30,12,IF(Consultas!AD5>'Parâmetros'!$A$31,6,IF(Consultas!AD5>'Parâmetros'!$A$32,0,IF(Consultas!AD5>'Parâmetros'!$A$33,0,IF(Consultas!AD5>'Parâmetros'!$A$34,-3,IF(Consultas!AD5>'Parâmetros'!$A$35,-7,-1))))))) -> 12 | AK5: =IF(Consultas!AO5='Parâmetros'!$D$1,3,-3) -> -3 | AL5: =IF(Consultas!AP5='Parâmetros'!$D$1,5,-3) -> -3 | AM5: =IF(Consultas!AL5="N",-6,0) -> 0 | AN5: =IF(Consultas!AM5="N",-10,0) -> 0 | AO5: =IF(Consultas!AN5="S",4,-2) -> -2 | AQ5: =IF(Consultas!F5>1,(SUM(F5:AO5)),"N/A") -> 59 | AR5: =IF((Consultas!AD5>'Parâmetros'!$A$31),"X",AJ5+Y5+V5+AC5) -> X | AS5: =IF((Consultas!AD5>'Parâmetros'!$A$31),"X",(H5+I5+J5+Q5+T5+Y5+Z5+AJ5+AN5)) -> X | AT5: =IF((Consultas!AD5<'Parâmetros'!$A$31),"X",(AD5+AC5+AB5)) -> 13 | AU5: =SMALL(AR5:AT5,1) -> 13 | AV5: =IF(AQ5="N/A","N/A",IF(AQ5>5,'Parâmetros'!$A$15,(IF(AU5=AR5,'Parâmetros'!$A$17,IF(AU5=AS5,'Parâmetros'!$A$16,'Parâmetros'!$A$14))))) -> SEM-RISCO | AW5: =IF(AQ5="N/A","N/A",IF(AV5='Parâmetros'!$A$15,'Parâmetros'!$C$15,(IF(AV5='Parâmetros'!$A$17,'Parâmetros'!$C$17,IF(AV5='Parâmetros'!$A$16,'Parâmetros'!$C$16,IF(AV5='Parâmetros'!$A$14,'Parâmetros'!$C$12)))))) -> LIBERADO | AX5: =IF(Consultas!F5>1,(IF(Consultas!F5>5000,"SOLICITAR PED COMPRA","N/A"))) -> N/A | AY5: =IF(AND(Consultas!M5<>"S", Consultas!H5="S"), "CHECAGEM REVERSA", "N/A") -> N/A | AZ5: =IF(Consultas!U5="N","PRECISA CORRIGIR END DIVERGENTE","N/A") -> N/A
A6: Define Risco | B6: =Consultas!B6 -> 442 | C6: =Consultas!D6 -> Oaco | D6: =Consultas!E6 -> 144469 | E6: =IF(Consultas!AB6>0,YEAR('Parâmetros'!$B$1)-YEAR(Consultas!AB6),"NA") -> 9 | F6: =IF(Consultas!F6>'Parâmetros'!$B$2,-8,0) -> 0 | G6: =IF(Consultas!H6='Parâmetros'!$E$1,100,0) -> 0 | H6: =IF(Consultas!I6='Parâmetros'!$E$1,-4,12) -> -4 | I6: =IF(Consultas!J6='Parâmetros'!$E$1,1,-13) -> 1 | J6: =IF(Consultas!K6='Parâmetros'!$E$1,2,-5) -> 2 | K6: =IF(Consultas!L6='Parâmetros'!$D$1,"SOLIC CONTRATO DE ENTREGA","N/A") -> N/A | L6: =IF(Consultas!R6='Parâmetros'!$E$1,1,-3) -> 1 | M6: =IF(Consultas!S6>1,(IF(Consultas!S6='Parâmetros'!$E$1,-3,9))) -> -3 | N6: =IF(Consultas!T6="S",23,0) -> 0 | O6: =IF(Consultas!U6='Parâmetros'!$E$1,-3,3) -> 3 | P6: =IF(Consultas!V6='Parâmetros'!$E$1,-100,2) -> 2 | Q6: =IF(Consultas!M6='Parâmetros'!$D$1,2,-9) -> 2 | R6: =IF(Consultas!N6="RJ",-12,0) -> 0 | S6: =IF(Consultas!O6="-",-3,IF(Consultas!O6=0,-6,IF(Consultas!O6=5,0,IF(Consultas!O6=10,6)))) -> -3 | T6: =IF(Consultas!M6="S",0,(IF(Consultas!P6="S",6,0))) -> 0 | U6: =IF(Consultas!Q6>97,9,IF(Consultas!Q6>75,0,-7)) -> 9 | V6: =IF(Consultas!W6='Parâmetros'!$E$1,1,-5) -> 1 | W6: =IF(Consultas!X6="S",3,-3) -> 3 | X6: =IF(Consultas!Y6="S",0,-7) -> 0 | Y6: =IF(Consultas!Z6='Parâmetros'!$E$1,2,-8) -> 2 | Z6: =IF(Consultas!AA6='Parâmetros'!$E$1,-15,1) -> 1 | AA6: - | AB6: =IF(E6="NA","NA",IF(E6>'Parâmetros'!$A$9,8,IF(E6>'Parâmetros'!$A$8,4,IF(E6>'Parâmetros'!$A$7,0,-6)))) -> 0 | AC6: =IF(Consultas!AC6='Parâmetros'!$E$1,0,5) -> 5 | AD6: =IF(Consultas!AH6='Parâmetros'!$D$1,-10,5) -> -10 | AE6: =IF(Consultas!AI6>(Consultas!F6*2),-10,0) -> -10 | AF6: =IF(Consultas!AD6>1,(IF(Consultas!AI6>(Consultas!AD6),-20,4))) -> 4 | AG6: =IF(Consultas!AG6='Parâmetros'!$E$1,0,-6) -> 0 | AH6: =IF(Consultas!AF6='Parâmetros'!$E$1,1,-5) -> -5 | AI6: =IF(Consultas!AJ6>700,8,IF(Consultas!AJ6>500,4,IF(Consultas!AJ6>200,-4,IF(Consultas!AJ6>1,-15,-20)))) -> 8 | AJ6: =IF(Consultas!AD6='Parâmetros'!$E$10,0,IF(Consultas!AD6>'Parâmetros'!$A$30,12,IF(Consultas!AD6>'Parâmetros'!$A$31,6,IF(Consultas!AD6>'Parâmetros'!$A$32,0,IF(Consultas!AD6>'Parâmetros'!$A$33,0,IF(Consultas!AD6>'Parâmetros'!$A$34,-3,IF(Consultas!AD6>'Parâmetros'!$A$35,-7,-1))))))) -> 12 | AK6: =IF(Consultas!AO6='Parâmetros'!$D$1,3,-3) -> -3 | AL6: =IF(Consultas!AP6='Parâmetros'!$D$1,5,-3) -> -3 | AM6: =IF(Consultas!AL6="N",-6,0) -> 0 | AN6: =IF(Consultas!AM6="N",-10,0) -> 0 | AO6: =IF(Consultas!AN6="S",4,-2) -> -2 | AQ6: =IF(Consultas!F6>1,(SUM(F6:AO6)),"N/A") -> 13 | AR6: =IF((Consultas!AD6>'Parâmetros'!$A$31),"X",AJ6+Y6+V6+AC6) -> X | AS6: =IF((Consultas!AD6>'Parâmetros'!$A$31),"X",(H6+I6+J6+Q6+T6+Y6+Z6+AJ6+AN6)) -> X | AT6: =IF((Consultas!AD6<'Parâmetros'!$A$31),"X",(AD6+AC6+AB6)) -> -5 | AU6: =SMALL(AR6:AT6,1) -> -5 | AV6: =IF(AQ6="N/A","N/A",IF(AQ6>5,'Parâmetros'!$A$15,(IF(AU6=AR6,'Parâmetros'!$A$17,IF(AU6=AS6,'Parâmetros'!$A$16,'Parâmetros'!$A$14))))) -> SEM-RISCO | AW6: =IF(AQ6="N/A","N/A",IF(AV6='Parâmetros'!$A$15,'Parâmetros'!$C$15,(IF(AV6='Parâmetros'!$A$17,'Parâmetros'!$C$17,IF(AV6='Parâmetros'!$A$16,'Parâmetros'!$C$16,IF(AV6='Parâmetros'!$A$14,'Parâmetros'!$C$12)))))) -> LIBERADO | AX6: =IF(Consultas!F6>1,(IF(Consultas!F6>5000,"SOLICITAR PED COMPRA","N/A"))) -> N/A | AY6: =IF(AND(Consultas!M6<>"S", Consultas!H6="S"), "CHECAGEM REVERSA", "N/A") -> N/A | AZ6: =IF(Consultas!U6="N","PRECISA CORRIGIR END DIVERGENTE","N/A") -> N/A
A7: Define Risco | B7: =Consultas!B7 -> 444 | C7: =Consultas!D7 -> Oaco | D7: =Consultas!E7 -> 144471 | E7: =IF(Consultas!AB7>0,YEAR('Parâmetros'!$B$1)-YEAR(Consultas!AB7),"NA") -> 9 | F7: =IF(Consultas!F7>'Parâmetros'!$B$2,-8,0) -> 0 | G7: =IF(Consultas!H7='Parâmetros'!$E$1,100,0) -> 0 | H7: =IF(Consultas!I7='Parâmetros'!$E$1,-4,12) -> -4 | I7: =IF(Consultas!J7='Parâmetros'!$E$1,1,-13) -> 1 | J7: =IF(Consultas!K7='Parâmetros'!$E$1,2,-5) -> 2 | K7: =IF(Consultas!L7='Parâmetros'!$D$1,"SOLIC CONTRATO DE ENTREGA","N/A") -> N/A | L7: =IF(Consultas!R7='Parâmetros'!$E$1,1,-3) -> 1 | M7: =IF(Consultas!S7>1,(IF(Consultas!S7='Parâmetros'!$E$1,-3,9))) -> -3 | N7: =IF(Consultas!T7="S",23,0) -> 0 | O7: =IF(Consultas!U7='Parâmetros'!$E$1,-3,3) -> 3 | P7: =IF(Consultas!V7='Parâmetros'!$E$1,-100,2) -> 2 | Q7: =IF(Consultas!M7='Parâmetros'!$D$1,2,-9) -> 2 | R7: =IF(Consultas!N7="RJ",-12,0) -> 0 | S7: =IF(Consultas!O7="-",-3,IF(Consultas!O7=0,-6,IF(Consultas!O7=5,0,IF(Consultas!O7=10,6)))) -> -3 | T7: =IF(Consultas!M7="S",0,(IF(Consultas!P7="S",6,0))) -> 0 | U7: =IF(Consultas!Q7>97,9,IF(Consultas!Q7>75,0,-7)) -> 9 | V7: =IF(Consultas!W7='Parâmetros'!$E$1,1,-5) -> 1 | W7: =IF(Consultas!X7="S",3,-3) -> 3 | X7: =IF(Consultas!Y7="S",0,-7) -> 0 | Y7: =IF(Consultas!Z7='Parâmetros'!$E$1,2,-8) -> 2 | Z7: =IF(Consultas!AA7='Parâmetros'!$E$1,-15,1) -> 1 | AA7: - | AB7: =IF(E7="NA","NA",IF(E7>'Parâmetros'!$A$9,8,IF(E7>'Parâmetros'!$A$8,4,IF(E7>'Parâmetros'!$A$7,0,-6)))) -> 0 | AC7: =IF(Consultas!AC7='Parâmetros'!$E$1,0,5) -> 5 | AD7: =IF(Consultas!AH7='Parâmetros'!$D$1,-10,5) -> -10 | AE7: =IF(Consultas!AI7>(Consultas!F7*2),-10,0) -> -10 | AF7: =IF(Consultas!AD7>1,(IF(Consultas!AI7>(Consultas!AD7),-20,4))) -> 4 | AG7: =IF(Consultas!AG7='Parâmetros'!$E$1,0,-6) -> 0 | AH7: =IF(Consultas!AF7='Parâmetros'!$E$1,1,-5) -> -5 | AI7: =IF(Consultas!AJ7>700,8,IF(Consultas!AJ7>500,4,IF(Consultas!AJ7>200,-4,IF(Consultas!AJ7>1,-15,-20)))) -> 8 | AJ7: =IF(Consultas!AD7='Parâmetros'!$E$10,0,IF(Consultas!AD7>'Parâmetros'!$A$30,12,IF(Consultas!AD7>'Parâmetros'!$A$31,6,IF(Consultas!AD7>'Parâmetros'!$A$32,0,IF(Consultas!AD7>'Parâmetros'!$A$33,0,IF(Consultas!AD7>'Parâmetros'!$A$34,-3,IF(Consultas!AD7>'Parâmetros'!$A$35,-7,-1))))))) -> 12 | AK7: =IF(Consultas!AO7='Parâmetros'!$D$1,3,-3) -> -3 | AL7: =IF(Consultas!AP7='Parâmetros'!$D$1,5,-3) -> -3 | AM7: =IF(Consultas!AL7="N",-6,0) -> 0 | AN7: =IF(Consultas!AM7="N",-10,0) -> 0 | AO7: =IF(Consultas!AN7="S",4,-2) -> -2 | AQ7: =IF(Consultas!F7>1,(SUM(F7:AO7)),"N/A") -> 13 | AR7: =IF((Consultas!AD7>'Parâmetros'!$A$31),"X",AJ7+Y7+V7+AC7) -> X | AS7: =IF((Consultas!AD7>'Parâmetros'!$A$31),"X",(H7+I7+J7+Q7+T7+Y7+Z7+AJ7+AN7)) -> X | AT7: =IF((Consultas!AD7<'Parâmetros'!$A$31),"X",(AD7+AC7+AB7)) -> -5 | AU7: =SMALL(AR7:AT7,1) -> -5 | AV7: =IF(AQ7="N/A","N/A",IF(AQ7>5,'Parâmetros'!$A$15,(IF(AU7=AR7,'Parâmetros'!$A$17,IF(AU7=AS7,'Parâmetros'!$A$16,'Parâmetros'!$A$14))))) -> SEM-RISCO | AW7: =IF(AQ7="N/A","N/A",IF(AV7='Parâmetros'!$A$15,'Parâmetros'!$C$15,(IF(AV7='Parâmetros'!$A$17,'Parâmetros'!$C$17,IF(AV7='Parâmetros'!$A$16,'Parâmetros'!$C$16,IF(AV7='Parâmetros'!$A$14,'Parâmetros'!$C$12)))))) -> LIBERADO | AX7: =IF(Consultas!F7>1,(IF(Consultas!F7>5000,"SOLICITAR PED COMPRA","N/A"))) -> N/A | AY7: =IF(AND(Consultas!M7<>"S", Consultas!H7="S"), "CHECAGEM REVERSA", "N/A") -> N/A | AZ7: =IF(Consultas!U7="N","PRECISA CORRIGIR END DIVERGENTE","N/A") -> N/A
